Workbook
Name EFFICIENCY: 'MC RATE'!$B$6:$J$18
Name MC_RATE_A: 'MC RATE'!$B$6:$C$38
Name MC_RATE_B: 'MC RATE'!$B$6:$D$38
Name SETUP_TIME: 'MC RATE'!$B$6:$G$38
Name SPM: 'MC RATE'!$B$6:$I$18
Name TM: 'MC RATE'!$B$6:$AE$38

Sheet Secondary Process MC
D2: Cost Components excluded in MSU Calculation: | E2: EXCL: | F2: EXCL: | G2: EXCL: | H2: EXCL:
E3: none
B6: Machine | C6: Machine Description | D6: Process Type | E6: MSU RATE A [US$/hr] | F6: MSU RATE B [US$/hr] | G6: MSU RATE C [US$/hr] | H6: MSU RATE D [US$/hr] | I6: MSU RATE E [US$/hr] | J6: MSU RATE Z [US$ / hr] | K6: Labour [US$ / hr] | L6: Labour Head Count / Hr [Man Power] | M6: Setup [US$ / hr] | N6: Qc [US$ / hr] | O6: Setup Time (Hr)
J7: Profit Cube Rate (No depriciation) | K7: Process Labour Cost per Hour | L7: Total Labour to operate a Machine for one hour in hours | M7: SU Cost per Hour | O7: SU Time in Hours
B8: T85001T | C8: 攻丝机 | D8: Sec Pro Tappig | E8: 2.7472217 | F8: 2.6531611 | G8: 0.97901414 | H8: 0.88495352 | K8: 3.25 | O8: 0.17
B9: T85002T | C9: 攻丝机 | D9: Sec Pro Tappig | E9: 3.2737241 | F9: 2.9106019 | G9: 1.5055166 | H9: 1.1423944 | K9: 3.25 | O9: 0.17
B10: R85001T | C10: 铆接机 | D10: Sec Pro Rivetting | E10: 2.247855 | F10: 2.1400619 | G10: 0.58624929 | H10: 0.47845624 | K10: 3.25 | O10: 0.17
B11: W85001T | C11: 点焊机 | D11: Sec ProcessWelding | E11: 7.3674735 | F11: 7.2447428 | G11: 5.7317049 | H11: 5.6089741 | K11: 3.25 | O11: 0.17
B12: W85001B1 | C12: 电解离子水清洗机 | D12: Degreasing | E12: 2.9417519 | F12: 2.8300665 | G12: 1.2196865 | H12: 1.1080011 | K12: 3.25 | O12: 0
B13: W85001B2 | C13: 超声波清洗机 | D13: Degreasing | E13: 24.311428 | F13: 20.175329 | G13: 21.754882 | H13: 17.618783 | K13: 3.25 | O13: 0
B14: H85001T | C14: 热熔 | D14: Heat Mounting | E14: 1.9319734 | F14: 1.9060221 | G14: 0.30653411 | H14: 0.28058273 | K14: 3.25 | O14: 0.17
B15: S85001AS | C15: 丝印 | D15: Silk Printing | E15: 4.0245489 | F15: 3.8163605 | G15: 2.3991096 | H15: 2.1909211 | K15: 3.25 | O15: 0
B16: ASF400R | C16: 弹簧机 | D16: Coiling Process | E16: 4.543497 | F16: 2.3609026 | G16: 4.3030028 | H16: 2.1204084 | K16: 3.25 | O16: 1
B17: AASY001 | C17: 组装线 | D17: Assembly Workcenter | E17: 7.0211953 | F17: 3.3100498 | G17: 5.806634 | H17: 2.0954885 | K17: 3.25 | O17: 0
B18: AASY002 | C18: 组装线 | D18: Assembly Workcenter | E18: 3.7353656 | F18: 3.0634895 | G18: 2.1437756 | H18: 1.4718995 | K18: 3.25 | O18: 0
B19: AASYEAL1 | C19: 组装线 | D19: Assembly Workcenter | E19: 3.7980225 | F19: 2.9751977 | G19: 2.699989 | H19: 1.8771641 | K19: 3.25 | O19: 0
... B25: P85001AS | C25: 组装线 | D25: Assembly Workcenter | E25: 3.2612028 | F25: 3.1148562 | G25: 1.1248838 | H25: 0.97853727 | K25: 3.25 | O25: 0.17
D30: Machine Cost / pc | E30: We check how many loads are required. If MOQ is lesser than the Qty / load, we will still use one full load. The full time per MOQ is calculated and the costs are divided by the MOQ
D31: Setup Cost / pc | E31: We first calculate how many setups are required for the MOQ. Number of Setups is multiplied with the Setup time and Rate and divided by MOQ
D32: Labour Cost / pc | E32: Labour cost depend on the Head count assigned to the process and the number per run. Then divided by the MOQ. No inline Packaging is assigned, only the operator. Inline packaging will be another process.
D33: Additional Cost / pc | E33: Fix items that are not in the MSU can be added inside additional costs. E.g. special tooling like expensive drills that need to be replaced after producing a certain amount
D34: Quality Cost / pc | E34: Quality work with the time required for quality. This inspection needs to be done when each run starts.

Sheet Stamping Process MC
D2: Cost Components excluded in MSU Calculation: | E2: EXCL: | F2: EXCL: | G2: EXCL: | H2: EXCL:
E3: none
B6: Machine | C6: Machine Description | D6: Process Type | E6: MSU RATE A [US$/hr] | F6: MSU RATE B [US$/hr] | G6: MSU RATE C [US$/hr] | H6: MSU RATE D [US$/hr] | I6: MSU RATE E [US$/hr] | J6: MSU RATE Z [US$ / hr] | K6: Labour [US$ / hr] | L6: Labour Head Count / Hr [Man Power] | M6: Setup [US$ / hr] | N6: Setup Time (hr) | O6: Labour Operation (LO) | P6: Labour Packaging (LP) | Q6: Labour Quality (LQ) | R6: DIR. LABOR-STAMP | S6: DIR. LABOR-PACKING | T6: QA / LOAD-STAMP
E7: Cost Components excluded in MSU Calculation: (None) | F7: Cost Components excluded in MSU Calculation: | G7: Cost Components excluded in MSU Calculation: | H7: Cost Components excluded in MSU Calculation: | J7: Profit Cube Rate (No depriciation) | K7: Process Labour Cost per Hour | L7: Total Labour to operate a Machine for one hour in hours | M7: SU Cost per Hour | N7: SU Time in Hours
B8: A75035T | C8: 35T 自动冲床 | D8: Progressive | E8: =VLOOKUP($B8,'MC RATE'!$A:$D,3,0) -> 13.672147 | F8: =VLOOKUP($B8,'MC RATE'!$A:$D,4,0) -> 9.0756919 | K8: 3.25 | N8: 0.37 | O8: 0.71428571 | P8: 0 | Q8: 0.28571429 | R8: 3.21
B9: A75060T | C9: 60T 自动冲床 | D9: Progressive | E9: =VLOOKUP($B9,'MC RATE'!$A:$D,3,0) -> 16.962004 | F9: =VLOOKUP($B9,'MC RATE'!$A:$D,4,0) -> 11.249737 | K9: 3.25 | N9: 0.37 | O9: 0.71428571 | P9: 0 | Q9: 0.28571429 | S9: 2.88 | T9: 5.06
B10: A75110T | C10: 110T 自动冲床 | D10: Progressive | E10: =VLOOKUP($B10,'MC RATE'!$A:$D,3,0) -> 17.159682 | F10: =VLOOKUP($B10,'MC RATE'!$A:$D,4,0) -> 11.593561 | K10: 3.25 | N10: 0.37 | O10: 0.71428571 | P10: 0 | Q10: 0.28571429
B11: A75160T | C11: 160T 自动冲床 | D11: Progressive | E11: =VLOOKUP($B11,'MC RATE'!$A:$D,3,0) -> 20.956628 | F11: =VLOOKUP($B11,'MC RATE'!$A:$D,4,0) -> 14.177566 | K11: 3.25 | N11: 0.45 | O11: 0.71428571 | P11: 0 | Q11: 0.28571429
B12: A75200T | C12: 200T 自动冲床 | D12: Progressive | E12: =VLOOKUP($B12,'MC RATE'!$A:$D,3,0) -> 25.715055 | F12: =VLOOKUP($B12,'MC RATE'!$A:$D,4,0) -> 17.621721 | K12: 3.25 | N12: 0.45 | O12: 0.71428571 | P12: 0 | Q12: 0.28571429
B13: A75300T | C13: 300T 自动冲床 | D13: Progressive | E13: =VLOOKUP($B13,'MC RATE'!$A:$D,3,0) -> 39.829524 | F13: =VLOOKUP($B13,'MC RATE'!$A:$D,4,0) -> 27.442444 | K13: 3.25 | N13: 0.55 | O13: 0.71428571 | P13: 0 | Q13: 0.28571429
B14: A75400T | C14: 400T 自动冲床 | D14: Progressive | E14: =VLOOKUP($B14,'MC RATE'!$A:$D,3,0) -> 50.906865 | F14: =VLOOKUP($B14,'MC RATE'!$A:$D,4,0) -> 35.281181 | K14: 3.25 | N14: 0.58 | O14: 0.8 | P14: 0 | Q14: 0.2
B15: M75060T | C15: 手动冲床 | D15: Manual | E15: =VLOOKUP($B15,'MC RATE'!$A:$D,3,0) -> 5.2054325 | F15: =VLOOKUP($B15,'MC RATE'!$A:$D,4,0) -> 3.5267577 | K15: 3.25 | N15: 0.33 | O15: 0.83333333 | P15: 0 | Q15: 0.16666667
B16: M75110T | C16: 手动冲床 | D16: Manual | E16: =VLOOKUP($B16,'MC RATE'!$A:$D,3,0) -> 6.6381157 | F16: =VLOOKUP($B16,'MC RATE'!$A:$D,4,0) -> 4.7034867 | K16: 3.25 | N16: 0.33 | O16: 0.83333333 | P16: 0 | Q16: 0.16666667
B17: M75160T | C17: 手动冲床 | D17: Manual | E17: =VLOOKUP($B17,'MC RATE'!$A:$D,3,0) -> 7.986119 | F17: =VLOOKUP($B17,'MC RATE'!$A:$D,4,0) -> 5.7019221 | K17: 3.25 | N17: 0.33 | O17: 0.83333333 | P17: 0 | Q17: 0.16666667
B18: M75200T | C18: 手动冲床 | D18: Manual | E18: =VLOOKUP($B18,'MC RATE'!$A:$D,3,0) -> 12.154753 | F18: =VLOOKUP($B18,'MC RATE'!$A:$D,4,0) -> 8.7019664 | K18: 3.25 | N18: 0.33 | O18: 0.83333333 | P18: 0 | Q18: 0.16666667
B19: M75300T | C19: 手动冲床 | D19: Manual | E19: =VLOOKUP($B19,'MC RATE'!$A:$D,3,0) -> 20.38528 | F19: =VLOOKUP($B19,'MC RATE'!$A:$D,4,0) -> 14.20747 | K19: 3.25 | N19: 0.33 | O19: 0.83333333 | P19: 0 | Q19: 0.16666667
D25: Machine Cost / pc | E25: Qty per Hr first calculate with 3600 divided by Cycle Time. If there is Effiency and cavity , Qty per Hr is mutipled with cavity and effiency%. Machine Cost/Pc is calculated MSU Rate divided by Qty per Hr.
D26: Setup Cost / pc | E26: We first calculate how many setups are required for the MOQ. Number of Setups is multiplied with the Setup time and Rate and divided by MOQ
D27: Labour Cost / pc | E27: Labour cost depend on the Head count assigned to the process and the number per run. Then divided by the MOQ. No inline Packaging is assigned, only the operator. Inline packaging will be another process.

Sheet SoftTool Process MC
B2: Machine | C2: Machine Description | D2: Process Type | E2: MSU RATE A [US$/hr] | F2: MSU RATE B [US$/hr] | G2: MSU RATE C [US$/hr] | H2: MSU RATE D [US$/hr] | I2: MSU RATE E [US$/hr] | J2: MSU RATE Z [US$ / hr] | K2: Labour [US$ / hr] | L2: Labour Head Count / Hr [Man Power] | M2: Setup [US$ / hr] | N2: Setup Time (hr) | O2: Capacity [SPM,Surface Area] | P2: Process Rate per Capacity
J3: Profit Cube Rate (No depriciation) | K3: Process Labour Cost per Hour | L3: Total Labour to operate a Machine for one hour in hours | M3: SU Cost per Hour | N3: SU Time in Hours | P3: Cost/Stroke or Mins or SurfaceArea
D21: Machine Cost / pc | E21: Qty per Hr first calculate with Strokes Per Minute is multipled with 60. Machine Cost/Pc is calculated MSU Rate divided by Qty per Hr.
D22: Setup Cost / pc | E22: We first calculate how many setups are required for the MOQ. Number of Setups is multiplied with the Setup time and Rate and divided by MOQ
D23: Labour Cost / pc | E23: Labour cost depend on the Head count assigned to the process and the number per run. Then divided by the MOQ. No inline Packaging is assigned, only the operator. Inline packaging will be another process.

Sheet ColdForging Process MC
B2: Machine | C2: Machine Description | D2: Process Type | E2: MSU RATE A [US$/hr] | F2: MSU RATE B [US$/hr] | G2: MSU RATE C [US$/hr] | H2: MSU RATE D [US$/hr] | I2: MSU RATE E [US$/hr] | J2: MSU RATE Z [US$ / hr] | K2: Labour [US$ / hr] | L2: Labour Head Count / Hr [Man Power] | M2: Setup [US$ / hr] | N2: Setup Time (hr)
J3: Profit Cube Rate (No depriciation) | K3: Process Labour Cost per Hour | L3: Total Labour to operate a Machine for one hour in hours | M3: SU Cost per Hour | N3: SU Time in Hours
D21: Machine Cost / pc | E21: Qty per Hr first calculate with 3600 divided by Cycle Time. If there is Effiency and cavity , Qty per Hr is mutipled with cavity and effiency%. Machine Cost/Pc is calculated MSU Rate divided by Qty per Hr.
D22: Setup Cost / pc | E22: We first calculate how many setups are required for the MOQ. Number of Setups is multiplied with the Setup time and Rate and divided by MOQ
D23: Labour Cost / pc | E23: Labour cost depend on the Head count assigned to the process and the number per run. Then divided by the MOQ. No inline Packaging is assigned, only the operator. Inline packaging will be another process.

Sheet DieCasting Process MC
B2: Machine | C2: Machine Description | D2: Process Type | E2: MSU RATE A [US$/hr] | F2: MSU RATE B [US$/hr] | G2: MSU RATE C [US$/hr] | H2: MSU RATE D [US$/hr] | I2: MSU RATE E [US$/hr] | J2: MSU RATE Z [US$ / hr] | K2: Labour [US$ / hr] | L2: Labour Head Count / Hr [Man Power] | M2: Setup [US$ / hr] | N2: Setup Time (hr)
J3: Profit Cube Rate (No depriciation) | K3: Process Labour Cost per Hour | L3: Total Labour to operate a Machine for one hour in hours | M3: SU Cost per Hour | N3: SU Time in Hours
D21: Machine Cost / pc | E21: Qty per Hr first calculate with 3600 divided by Cycle Time. If there is Effiency and cavity , Qty per Hr is mutipled with cavity and effiency%. Machine Cost/Pc is calculated MSU Rate divided by Qty per Hr.
D22: Setup Cost / pc | E22: We first calculate how many setups are required for the MOQ. Number of Setups is multiplied with the Setup time and Rate and divided by MOQ
D23: Labour Cost / pc | E23: Labour cost depend on the Head count assigned to the process and the number per run. Then divided by the MOQ. No inline Packaging is assigned, only the operator. Inline packaging will be another process.

Sheet Factory Labour and MasterData
C1: US$
A2: selfEvaporatingOilFinishingRate [US$] | B2: Self Evaporating Oil Finshing Rate | C2: 0.0025
A3: degreasingFinishingRate [US$] | B3: Degreasing Finishing Rate | C3: 0.005
A4: labourCostAssembly [US$] | B4: Labour Cost (Assembly) for Assembly Process | C4: 3.25
A5: labourCostEngineering [US$] | B5: Labour Cost (Engineering) | C5: 3.25
A6: labourCostFloorArea [US$] | B6: Floor Area Cost per sq meter | C6: 3.25
A7: labourCostPackaging [US$] | B7: Labour Cost (Packaging) | C7: 3.25
A10: New Investment | B10: New Investment
A12: factoryElectricalPower [US$] | B12: Electrical Cost / kwh
A13: factoryWaterCuM [US$] | B13: Water/ Coolant Rate per Cu.m
A14: factoryAllowancePercent [%] | B14: Allowance Percent for Direct Labour ( the data is needed to calculate Allowance / Month)
A15: factoryEmpContrPercent [%] | B15: Emp Contr Percent for Direct Labour (the data is needed to calculate Emp Contr/Month)
A17: mcOperatorBasicSalaryPerMth [US$] | B17: M/C Operators Basic Salary Per Month
A18: packerBasicSalaryPerMth [US$] | B18: Packer Basic Salary Per Month
A19: materialHandlerBasicSalaryPerMth [US$] | B19: Material Handler Basic Salary Per Month
A20: qcInspectorBasicSalaryPerMth [US$] | B20: QC Inspector Basic Salary Per Month
A21: clerkBasicSalaryPerMth [US$] | B21: Clerk Basic Salary Per Month
A22: storeKeeperBasicSalaryPerMth [US$] | B22: Store Keeper Basic Salary Per Month
A23: driverBasicSalaryPerMth [US$] | B23: Driver Basic Salary Per Month
... A28: processEngineerBasicSalaryPerMth [US$] | B28: Process Engineer Basic Salary Per Month

Sheet Reference-->

Sheet MC RATE
B1: HOURLY MACHINE RATE FOR AMTEK INDUSTRIES (AHIL / AZIL) | K1: factor= | L1: 0.9
K2: 10 | L2: 11 | M2: 12 | N2: 13 | O2: 14 | P2: 15 | Q2: 16 | R2: 17 | S2: 18 | T2: 19 | U2: 20 | V2: 21 | W2: 22 | X2: 23 | Y2: 24 | Z2: 25 | AA2: 26 | AB2: 27 | AC2: 28 | AD2: 29 | AE2: 30
C3: AHIL/AZIL MACHINE RATE (USD) | K3: CRS/BRASS/COPPER/Alu 1100/ Alu 3033 | R3: COATED ZINC/ Alu 5052/ Alu 6061 | Y3: SUS / C45 / Bimetal
B4: MACHINE # | C4: A | D4: B | E4: M/C TYPE | F4: PROCESS | G4: SETUP TIME | H4: OUTPUT/HR | I4: SPM | J4: EFFICIENCY | K4: 0.05<t<0.25 | L4: 0.25<t<0.5 | M4: 0.5<t<1.0 | N4: 1.1<t<1.5 | O4: 1.6<t<2.0 | P4: 2.0<t<2.6 | Q4: 2.6<t<3.2 | R4: 0.05<t<0.25 | S4: 0.25<t<0.5 | T4: 0.5<t<1.0 | U4: 1.1<t<1.5 | V4: 1.6<t<2.0 | W4: 2.0<t<2.6 | X4: 2.6<t<3.2 | Y4: 0.05<t<0.25 | Z4: 0.25<t<0.5 | AA4: 0.5<t<1.0 | AB4: 1.1<t<1.5 | AC4: 1.6<t<2.0 | AD4: 2.0<t<2.6 | AE4: 2.6<t<3.2
B5: 0 | C5: 3 shift | D5: 2 shift
A6: A75035T | B6: 1035 | C6: 13.672147 | D6: 9.0756919 | E6: A35 | F6: Progressive | G6: 0.6 | H6: =I6*60*J6/100 -> 5616 | I6: 117 | J6: 80 | K6: 2.484 | L6: 0.79615385 | M6: 0.59142857 | N6: 0.69 | O6: 1.38 | P6: 2.484 | Q6: 3.105 | R6: 2.1 | S6: 0.96923077 | T6: 0.84 | U6: 1.008 | V6: 1.68 | W6: 3.024 | X6: 3.78 | Y6: 3.4666667 | Z6: 2.1272727 | AA6: 1.872 | AB6: 2.34 | AC6: 3.12 | AD6: 3.4666667 | AE6: 3.9
A7: A75060T | B7: 1060 | C7: 16.962004 | D7: 11.249737 | E7: A60 | F7: Progressive | G7: 0.6 | H7: =I7*60*J7/100 -> 3648 | I7: 76 | J7: 80 | K7: 2.484 | L7: 0.79615385 | M7: 0.59142857 | N7: 0.69 | O7: 1.38 | P7: 2.484 | Q7: 3.105 | R7: 2.1 | S7: 0.96923077 | T7: 0.84 | U7: 1.008 | V7: 1.68 | W7: 3.024 | X7: 3.78 | Y7: 3.4666667 | Z7: 2.1272727 | AA7: 1.872 | AB7: 2.34 | AC7: 3.12 | AD7: 3.4666667 | AE7: 3.9
A8: A75110T | B8: 1110 | C8: 17.159682 | D8: 11.593561 | E8: A110 | F8: Progressive | G8: 0.7 | H8: =I8*60*J8/100 -> 2976 | I8: 62 | J8: 80 | K8: 3.456 | L8: 1.1076923 | M8: 0.82285714 | N8: 0.96 | O8: 1.92 | P8: 3.456 | Q8: 5.229 | R8: 3.402 | S8: 1.566 | T8: 1.359 | U8: 1.629 | V8: 2.718 | W8: 5.436 | X8: 6.12 | Y8: 5.202 | Z8: 3.195 | AA8: 2.808 | AB8: 3.51 | AC8: 5.616 | AD8: 5.202 | AE8: 5.85
A9: A75160T | B9: 1160 | C9: 20.956628 | D9: 14.177566 | E9: A160 | F9: Progressive | G9: 0.8 | H9: =I9*60*J9/100 -> 2196 | I9: 61 | J9: 60 | K9: 4.1796 | L9: 1.3396154 | M9: 0.99514286 | N9: 1.161 | O9: 2.322 | P9: 4.1796 | Q9: 5.2245 | R9: 3.3975 | S9: 1.5680769 | T9: 1.359 | U9: 1.6308 | V9: 2.718 | W9: 5.436 | X9: 6.1155 | Y9: 5.2 | Z9: 3.1909091 | AA9: 2.808 | AB9: 3.51 | AC9: 5.616 | AD9: 5.2 | AE9: 5.85
A10: A75200T | B10: 1200 | C10: 25.715055 | D10: 17.621721 | E10: A200 | F10: Progressive | G10: 0.9 | H10: =I10*60*J10/100 -> 1908 | I10: 53 | J10: 60 | K10: 4.6116 | L10: 1.4780769 | M10: 1.098 | N10: 1.281 | O10: 2.562 | P10: 4.6116 | Q10: 5.7645 | R10: 3.6975 | S10: 1.7065385 | T10: 1.479 | U10: 1.7748 | V10: 2.958 | W10: 5.916 | X10: 6.6555 | Y10: 5.6 | Z10: 3.4363636 | AA10: 3.024 | AB10: 3.78 | AC10: 6.048 | AD10: 5.6 | AE10: 6.3
B11: 1250 | C11: 37.788088 | D11: 25.745712 | E11: A250 | F11: Progressive | G11: 1 | H11: =I11*60*J11/100 -> 1590 | I11: 53 | J11: 50 | K11: 6.1884 | L11: 1.9834615 | M11: 1.4734286 | N11: 1.719 | O11: 3.438 | P11: 6.1884 | Q11: 7.7355 | R11: 4.8 | S11: 2.2153846 | T11: 1.92 | U11: 2.304 | V11: 3.84 | W11: 7.68 | X11: 8.64 | Y11: 7.0666667 | Z11: 4.3363636 | AA11: 3.816 | AB11: 4.77 | AC11: 7.632 | AD11: 7.0666667 | AE11: 7.95
A12: A75300T | B12: 1300 | C12: 39.829524 | D12: 27.442444 | E12: A300 | F12: Progressive | G12: 1.1 | H12: =I12*60*J12/100 -> 1590 | I12: 53 | J12: 50 | K12: 7.776 | L12: 2.4923077 | M12: 1.8514286 | N12: 2.16 | O12: 4.32 | P12: 7.776 | Q12: 9.72 | R12: 5.9025 | S12: 2.7242308 | T12: 2.361 | U12: 2.8332 | V12: 4.722 | W12: 9.444 | X12: 10.6245 | Y12: 8.5333333 | Z12: 5.2363636 | AA12: 4.608 | AB12: 5.76 | AC12: 9.216 | AD12: 8.5333333 | AE12: 9.6
A13: A75400T | B13: 1400 | C13: 50.906865 | D13: 35.281181 | E13: A400 | F13: Progressive | G13: 1.2 | H13: =I13*60*J13/100 -> 1050 | I13: 35 | J13: 50 | K13: 8.9316 | L13: 2.8626923 | M13: 2.1265714 | N13: 2.481 | O13: 4.962 | P13: 8.9316 | Q13: 11.1645 | R13: 6.6975 | S13: 3.0911538 | T13: 2.679 | U13: 3.2148 | V13: 5.358 | W13: 10.716 | X13: 12.0555 | Y13: 9.6 | Z13: 5.8909091 | AA13: 5.184 | AB13: 6.48 | AC13: 10.368 | AD13: 9.6 | AE13: 10.8
A14: M75060T | B14: 2060 | C14: 5.2054325 | D14: 3.5267577 | E14: M60 | F14: Manual | G14: 0.5 | H14: =I14*60*J14/100 -> 546 | I14: 13 | J14: 70 | K14: 1.6632 | L14: 0.53307692 | M14: 0.396 | N14: 0.462 | O14: 0.924 | P14: 1.6632 | Q14: 2.079 | R14: 1.431375 | S14: 0.66063462 | T14: 0.57255 | U14: 0.68706 | V14: 1.1451 | W14: 2.2902 | X14: 2.576475 | Y14: 2.2733333 | Z14: 1.395 | AA14: 1.2276 | AB14: 1.5345 | AC14: 2.4552 | AD14: 2.2733333 | AE14: 2.5575
A15: M75110T | B15: 2110 | C15: 6.6381157 | D15: 4.7034867 | E15: M110 | F15: Manual | G15: 0.5 | H15: =I15*60*J15/100 -> 546 | I15: 13 | J15: 70 | K15: 2.29878 | L15: 0.73678846 | M15: 0.54732857 | N15: 0.63855 | O15: 1.2771 | P15: 2.29878 | Q15: 2.873475 | R15: 1.868625 | S15: 0.86244231 | T15: 0.74745 | U15: 0.89694 | V15: 1.4949 | W15: 2.9898 | X15: 3.363525 | Y15: 2.86 | Z15: 1.755 | AA15: 1.5444 | AB15: 1.9305 | AC15: 3.0888 | AD15: 2.86 | AE15: 3.2175
A16: M75160T | B16: 2160 | C16: 7.986119 | D16: 5.7019221 | E16: M160 | F16: Manual | G16: 0.6 | H16: =I16*60*J16/100 -> 420 | I16: 10 | J16: 70 | K16: 2.53638 | L16: 0.81294231 | M16: 0.6039 | N16: 0.70455 | O16: 1.4091 | P16: 2.53638 | Q16: 3.170475 | R16: 2.033625 | S16: 0.93859615 | T16: 0.81345 | U16: 0.97614 | V16: 1.6269 | W16: 3.2538 | X16: 3.660525 | Y16: 3.08 | Z16: 1.89 | AA16: 1.6632 | AB16: 2.079 | AC16: 3.3264 | AD16: 3.08 | AE16: 3.465
A17: M75200T | B17: 2200 | C17: 12.154753 | D17: 8.7019664 | E17: M200 | F17: Manual | G17: 0.6 | H17: =I17*60*J17/100 -> 420 | I17: 10 | J17: 70 | K17: 3.40362 | L17: 1.0909038 | M17: 0.81038571 | N17: 0.94545 | O17: 1.8909 | P17: 3.40362 | Q17: 4.254525 | R17: 2.64 | S17: 1.2184615 | T17: 1.056 | U17: 1.2672 | V17: 2.112 | W17: 4.224 | X17: 4.752 | Y17: 3.8866667 | Z17: 2.385 | AA17: 2.0988 | AB17: 2.6235 | AC17: 4.1976 | AD17: 3.8866667 | AE17: 4.3725
A18: M75300T | B18: 2300 | C18: 20.38528 | D18: 14.20747 | E18: M300 | F18: Manual | G18: 0.8 | H18: =I18*60*J18/100 -> 294 | I18: 7 | J18: 70 | K18: 3.40362 | L18: 1.0909038 | M18: 0.81038571 | N18: 0.94545 | O18: 1.8909 | P18: 3.40362 | Q18: 4.254525 | R18: 2.64 | S18: 1.2184615 | T18: 1.056 | U18: 1.2672 | V18: 2.112 | W18: 4.224 | X18: 4.752 | Y18: 3.8866667 | Z18: 2.385 | AA18: 2.0988 | AB18: 2.6235 | AC18: 4.1976 | AD18: 3.8866667 | AE18: 4.3725
B19: 6010 | C19: 5 | D19: 5 | E19: 1 Spindle Tap | F19: Tapping
B20: 6012 | C20: NA | D20: NA | E20: 2 Spindle | F20: Tapping
B21: 6013 | C21: NA | D21: NA | E21: 3 Spindle | F21: Tapping
B22: 6014 | C22: NA | D22: NA | E22: 4 Spindle | F22: Tapping
B23: 6015 | C23: NA | D23: NA | E23: 5 Spindle | F23: Tapping
B24: 6016 | C24: NA | D24: NA | E24: 6 Spindle | F24: Tapping
B25: 6017 | C25: NA | D25: NA | E25: 7 Spindle | F25: Tapping
B26: 6018 | C26: NA | D26: NA | E26: 8 Spindle | F26: Tapping
B27: 6019 | C27: NA | D27: NA | E27: 9 Spindle | F27: Tapping
B28: 6020 | C28: NA | D28: NA | E28: 10 Spindle | F28: Tapping
B29: 6100 | C29: 9.6 | D29: 9.6 | E29: Multi ST | F29: Tapping
B30: 6200 | C30: NA | D30: NA | E30: AUTOTAP | F30: Auto Tap
B31: 6300 | C31: 3.7 | D31: 3.7 | E31: DRILL | F31: Drill
B32: 6500 | C32: 6.4 | D32: 6.4 | E32: S/RIVET | F32: Rivet
B33: 6600 | C33: 16 | D33: 16 | E33: STAKE 6T | F33: Staking
B34: 7025 | C34: 6.9 | D34: 6.9 | E34: 25 KVA | F34: Spot Weld | G34: 0.5 | H34: 200
B35: 7035 | C35: 8.7 | D35: 8.7 | E35: 35 KVA | F35: Spot Weld | G35: 0.5 | H35: 200
B36: 7065 | C36: 16 | D36: 16 | E36: 65 KVA | F36: Spot Weld | G36: 0.5 | H36: 200
B37: 7360 | C37: NA | D37: NA | E37: 360KVA | F37: Spot Weld | G37: 1 | H37: 200
B38: 7480 | C38: NA | D38: NA | E38: 480KVA | F38: Spot Weld | G38: 1 | H38: 200
B41: PRESSBRAKE @ US$0.16/BEND,
B42: TAPPING @ US$0.013/HOLE,
...
